<?xml version="1.0"?>
<robot name="duckiebot">
  <link name="base_link"/>
  <link name="r0_base_link"/>
  <link name="r0">
    <visual>
      <origin xyz="0.0 0.0 0.04" rpy="0.0 0.0 3.14159265359"/>
      <geometry>
        <mesh filename="package://duckietown_description/urdf/meshes/duckiebot.dae"/>
      </geometry>
    </visual>
    <collision>
      <geometry>
        <box size="0.25 0.15 0.02"/>
      </geometry>
    </collision>
  </link>
  <joint name="r0_base_joint" type="planar">
    <parent link="r0_base_link"/>
    <child link="r0"/>
  </joint>
  <joint name="r0_world_joint" type="floating">
    <origin xyz="0 0.0 0.0" rpy="0 0 0"/>
    <parent link="base_link"/>
    <child link="r0_base_link"/>
  </joint>
  <link name="r1_base_link"/>
  <link name="r1">
    <visual>
      <origin xyz="0.0 0.0 0.04" rpy="0.0 0.0 3.14159265359"/>
      <geometry>
        <mesh filename="package://duckietown_description/urdf/meshes/duckiebot.dae"/>
      </geometry>
    </visual>
    <collision>
      <geometry>
        <box size="0.25 0.15 0.02"/>
      </geometry>
    </collision>
  </link>
  <joint name="r1_base_joint" type="planar">
    <parent link="r1_base_link"/>
    <child link="r1"/>
  </joint>
  <joint name="r1_world_joint" type="floating">
    <origin xyz="0 0.25 0.0" rpy="0 0 0"/>
    <parent link="base_link"/>
    <child link="r1_base_link"/>
  </joint>
  <link name="r2_base_link"/>
  <link name="r2">
    <visual>
      <origin xyz="0.0 0.0 0.04" rpy="0.0 0.0 3.14159265359"/>
      <geometry>
        <mesh filename="package://duckietown_description/urdf/meshes/duckiebot.dae"/>
      </geometry>
    </visual>
    <collision>
      <geometry>
        <box size="0.25 0.15 0.02"/>
      </geometry>
    </collision>
  </link>
  <joint name="r2_base_joint" type="planar">
    <parent link="r2_base_link"/>
    <child link="r2"/>
  </joint>
  <joint name="r2_world_joint" type="floating">
    <origin xyz="0 0.5 0.0" rpy="0 0 0"/>
    <parent link="base_link"/>
    <child link="r2_base_link"/>
  </joint>
  <link name="r3_base_link"/>
  <link name="r3">
    <visual>
      <origin xyz="0.0 0.0 0.04" rpy="0.0 0.0 3.14159265359"/>
      <geometry>
        <mesh filename="package://duckietown_description/urdf/meshes/duckiebot.dae"/>
      </geometry>
    </visual>
    <collision>
      <geometry>
        <box size="0.25 0.15 0.02"/>
      </geometry>
    </collision>
  </link>
  <joint name="r3_base_joint" type="planar">
    <parent link="r3_base_link"/>
    <child link="r3"/>
  </joint>
  <joint name="r3_world_joint" type="floating">
    <origin xyz="0 0.75 0.0" rpy="0 0 0"/>
    <parent link="base_link"/>
    <child link="r3_base_link"/>
  </joint>
</robot>
