<?xml version="1.0" ?>
<robot name="triplebot" xmlns:xacro="http://ros.org/wiki/xacro">

  <xacro:property name="width" value="0.15" />
  <xacro:property name="length" value="0.25" />
  <material name="blue">
    <color rgba="0 0 1 1"/>
  </material>
  <material name="yellow">
    <color rgba="1 1 0 1"/>
  </material>
  <material name="white">
    <color rgba="1 1 1 1"/>
  </material>

  <link name="base">	
	</link>

  <link name="r1_base">	
	</link>

  <link name="r2_base">	
	</link>

  <link name="r3_base">	
	</link>

  <link name="r1">
    <visual>
      <geometry>
        <box size="${length} ${width} 0.02"/>
      </geometry>
      <material name="blue"/>
    </visual>
    <collision>
      <geometry>
        <box size="${length} ${width} 0.02"/>
      </geometry>
    </collision> 
	</link>

  <link name="r2">
    <visual>
      <geometry>
        <box size="${length} ${width} 0.02"/>
      </geometry>
      <material name="yellow"/>
    </visual>
    <collision>
      <geometry>
        <box size="${length} ${width} 0.02"/>
      </geometry>
    </collision>
	</link>

  <link name="r3">
    <visual>
      <geometry>
        <box size="${length} ${width} 0.02"/>
      </geometry>
      <material name="white"/>
    </visual>
    <collision>
      <geometry>
        <box size="${length} ${width} 0.02"/>
      </geometry>
    </collision>
	</link>

  <joint name="r1_world_base_joint" type="floating">
    <parent link="base"/>
    <child link="r1_base"/>
	</joint>

  <joint name="r2_world_base_joint" type="floating">
    <parent link="base"/>
    <child link="r2_base"/>
		<origin xyz="0 0.25 0" rpy="0 0 0"/>
	</joint>

	<joint name="r3_world_base_joint" type="floating">
    <parent link="base"/>
    <child link="r3_base"/>
		<origin xyz="0 -0.25 0" rpy="0 0 0"/>
	</joint>

  <joint name="r1_base_joint" type="planar">
    <parent link="r1_base"/>
    <child link="r1"/>
	</joint>

  <joint name="r2_base_joint" type="planar">
    <parent link="r2_base"/>
    <child link="r2"/>
	</joint>

  <joint name="r3_base_joint" type="planar">
    <parent link="r3_base"/>
    <child link="r3"/>
	</joint>


</robot>
